Workbook

Sheet Dashboard
A1: 📊 Französisch Grammatik Tracker - Dashboard
A3: Gesamtstatistik
A4: Gesamt Konzepte: | B4: =COUNTA('Grammatik Tracker'!B:B)-1 -> 317
A5: Neue Konzepte: | B5: =COUNTIF('Grammatik Tracker'!I:I,"Neu") -> 272
A6: Ausbaufähig: | B6: =COUNTIF('Grammatik Tracker'!I:I,"Ausbaufähig") -> 4
A7: In Arbeit: | B7: =COUNTIF('Grammatik Tracker'!I:I,"In Arbeit") -> 39
A8: Gefestigt: | B8: =COUNTIF('Grammatik Tracker'!I:I,"Gefestigt") -> 2
A9: Gemeistert: | B9: =COUNTIF('Grammatik Tracker'!I:I,"Gemeistert") -> 0
A12: Verteilung nach Niveau
A13: A1: | B13: =COUNTIF('Grammatik Tracker'!C:C,"A1") -> 37
A14: A2: | B14: =COUNTIF('Grammatik Tracker'!C:C,"A2") -> 36
A15: B1: | B15: =COUNTIF('Grammatik Tracker'!C:C,"B1") -> 54
A16: B2: | B16: =COUNTIF('Grammatik Tracker'!C:C,"B2") -> 54
A17: C1: | B17: =COUNTIF('Grammatik Tracker'!C:C,"C1") -> 65
A18: C2: | B18: =COUNTIF('Grammatik Tracker'!C:C,"C2") -> 71
A20: Lernfortschritt
A21: Durchschn. Score: | B21: =ROUND(AVERAGEIF('Grammatik Tracker'!E:E,">0",'Grammatik Tracker'!E:E),1) -> 6.8
A22: Gesamte Wiederholungen: | B22: =SUM('Grammatik Tracker'!F:F) -> 66
A23: Konzepte mit Score: | B23: =COUNTA('Grammatik Tracker'!E2:E247)-COUNTBLANK('Grammatik Tracker'!E2:E247) -> -156
A24: Fortschritt: | B24: =TEXT(B23/B4,"0%") -> -49%

Sheet Grammatik Tracker
A1: ID | B1: Grammatik Konzept | C1: Niveau | D1: Letzte Wiederholung | E1: Score (0-10) | F1: Anzahl Wiederholungen | G1: Notizen | H1: Nächste Wiederholung | I1: Status | J1: Auswählen
A2: 75 | B2: B1 – Plus-que-parfait: Bildung & Gebrauch | C2: B1 | D2: 45980 | E2: 6 | F2: 1 | G2: Der zeitliche Gebrauch (Vorphänomen in der Vergangenheit) ist verstanden, aber bei der Bildung gab es wiederholt Probleme mit der Wahl des Hilfsverbs (avoir vs. être) und mit Partizipformen (z.B. avions parti, avait meurt statt étions partis, était morte). Auch die Einbindung von Adverbien (déjà) ins Plus-que-parfait klappt meist, formale Details brauchen jedoch noch | H2: =IF(AND(E2<>"",D2<>""),IF(E2>=9,D2+30,IF(E2>=7,D2+14,IF(E2>=5,D2+7,IF(E2>=3,D2+3,D2+1)))),"") -> 45987 | I2: =IF(F2=0,"Neu",IF(AND(E2>=9,F2>=3),"Gemeistert",IF(E2>=9,"Gefestigt",IF(E2>=5,"In Arbeit","Ausbaufähig")))) -> In Arbeit
A3: 173 | B3: B2 – Opposition/Einräumung: cependant, toutefois | C3: B2 | D3: 45974 | E3: 8 | F3: 1 | G3: Bedeutung und Funktion als Konnektor (Kontrast) sind klar, und die Einbindung in Sätze gelingt meist gut; kleinere Detailprobleme betreffen v.a. Zeichensetzung/Position im Satz und die stilistische Abgrenzung zu einfacheren Konjunktionen wie mais. | H3: =IF(AND(E3<>"",D3<>""),IF(E3>=9,D3+30,IF(E3>=7,D3+14,IF(E3>=5,D3+7,IF(E3>=3,D3+3,D3+1)))),"") -> 45988 | I3: =IF(F3=0,"Neu",IF(AND(E3>=9,F3>=3),"Gemeistert",IF(E3>=9,"Gefestigt",IF(E3>=5,"In Arbeit","Ausbaufähig")))) -> In Arbeit
A4: 159 | B4: B2 – Vergleich & Grad: plus/moins/autant | C4: B2 | D4: 45974 | E4: 7 | F4: 1 | G4: Strukturen wie plus/moins … que sitzen überwiegend sicher, ebenso bei Adjektiven; Unsicherheiten gibt es noch bei autant de vs. aussi und der Kombination mit Nomen (autant de travail que toi), sowie gelegentlich bei der Semantik (“früher” = avant, nicht plus tôt). | H4: =IF(AND(E4<>"",D4<>""),IF(E4>=9,D4+30,IF(E4>=7,D4+14,IF(E4>=5,D4+7,IF(E4>=3,D4+3,D4+1)))),"") -> 45988 | I4: =IF(F4=0,"Neu",IF(AND(E4>=9,F4>=3),"Gemeistert",IF(E4>=9,"Gefestigt",IF(E4>=5,"In Arbeit","Ausbaufähig")))) -> In Arbeit
A5: 141 | B5: B2 – Relativpronomen: dont, ce dont | C5: B2 | D5: 45981 | E5: 6 | F5: 2 | G5: dont nach Verben/Ausdrücken mit de meist korrekt; Unsicherheit bei ce dont vs. ce que/ce qui (Dopplung dont … devermeiden; „de-Test“ nutzen). Interferenz mit Verben ohne de (raconter → ce que, nicht dont). /// 2.wdh:Die Funktion von dont nach Verben mit de ist grundsätzlich verstanden, jedoch kommt es in der freien Produktion noch zu Verwechslungen zwischen dont/ce dont und ce que (z.B. mit raconter, dire) sowie zu überflüssigem de. Der „de-Test“ wird nicht immer zuverlässig angewendet, besonders wenn bereits ein Bezugsnomen vorhanden ist. | H5: =IF(AND(E5<>"",D5<>""),IF(E5>=9,D5+30,IF(E5>=7,D5+14,IF(E5>=5,D5+7,IF(E5>=3,D5+3,D5+1)))),"") -> 45988 | I5: =IF(F5=0,"Neu",IF(AND(E5>=9,F5>=3),"Gemeistert",IF(E5>=9,"Gefestigt",IF(E5>=5,"In Arbeit","Ausbaufähig")))) -> In Arbeit
A6: 81 | B6: B1 – Si-Sätze Typ 1: si + présent → futur | C6: B1 | D6: 45975 | E6: 8 | F6: 1 | G6: Grundstruktur si + Présent → Futur sitzt sicher, nur vereinzelt Tendenz, Futur im si-Teil zu verwenden und kleine Lexikfehler (z.B. Verbwahl bei „Film schauen“). In spontanen Sätzen weitgehend korrekt. | H6: =IF(AND(E6<>"",D6<>""),IF(E6>=9,D6+30,IF(E6>=7,D6+14,IF(E6>=5,D6+7,IF(E6>=3,D6+3,D6+1)))),"") -> 45989 | I6: =IF(F6=0,"Neu",IF(AND(E6>=9,F6>=3),"Gemeistert",IF(E6>=9,"Gefestigt",IF(E6>=5,"In Arbeit","Ausbaufähig")))) -> In Arbeit
A7: 105 | B7: B1 – Adjektive der Farbe: Unveränderlichkeit | C7: B1 | D7: 45975 | E7: 8 | F7: 1 | G7: Unterschied zwischen veränderlichen Grundfarben und unveränderlichen zusammengesetzten bzw. von Nomen abgeleiteten Farben (orange, marron, bleu clair) ist größtenteils sicher; einmalige Unsicherheit bei Kombinationen und ein Angleichungsfehler am Participe passé, der eher nicht zum Farbthema gehört. | H7: =IF(AND(E7<>"",D7<>""),IF(E7>=9,D7+30,IF(E7>=7,D7+14,IF(E7>=5,D7+7,IF(E7>=3,D7+3,D7+1)))),"") -> 45989 | I7: =IF(F7=0,"Neu",IF(AND(E7>=9,F7>=3),"Gemeistert",IF(E7>=9,"Gefestigt",IF(E7>=5,"In Arbeit","Ausbaufähig")))) -> In Arbeit
A8: 82 | B8: B1 – Si-Sätze Typ 2: si + imparfait → conditionnel | C8: B1 | D8: 45975 | E8: 7 | F8: 1 | G8: Regel si + Imparfait → Conditionnel ist verstanden, anfangs Mischformen mit Futur/Conditionnel, später deutlich stabiler; vereinzelt kleine Formfehler (z.B. Elision „Si j’habitais“). Hypothetische Aussagen gelingen schon recht flüssig. | H8: =IF(AND(E8<>"",D8<>""),IF(E8>=9,D8+30,IF(E8>=7,D8+14,IF(E8>=5,D8+7,IF(E8>=3,D8+3,D8+1)))),"") -> 45989 | I8: =IF(F8=0,"Neu",IF(AND(E8>=9,F8>=3),"Gemeistert",IF(E8>=9,"Gefestigt",IF(E8>=5,"In Arbeit","Ausbaufähig")))) -> In Arbeit
A9: 148 | B9: B2 – Demonstrativpronomen: celui/celle/ceux/celles | C9: B2 | D9: 45986 | E9: 4 | F9: 3 | G9: Grundidee ist da, aber häufig werden die Formen mit Begleitern wie ce/cette vermischt oder in falschem Genus/ohne klaren Bezug verwendet (celui livre, celui für recette); der Unterschied „Pronomen ersetzt das Nomen vollständig“ ist noch nicht stabil verinnerlicht. //// 1. WDH: Grundidee ist klar, aber es kommt zu Verwechslungen zwischen „ce/cette“ und „celui/celle“ und zu falscher Verwendung von „celui“ ohne klaren Bezug. Genus/Zahl sind noch nicht völlig stabil (z.B. „ceux“ statt „celui“, „celui“ statt „celles“) und gelegentlich wird „ceux“ anstelle des COD-Pronomens „les“ benutzt. /// 2. WDH: Teilweise richtige Wahl (ceux, celle), aber noch deutliche Verwechslung von Pronomen und Begleitern (ce/cette/ces), falsche Zuordnung von Genus/Zahl und unsicherer Bezug (« ceux » für feminine Referenten, unklare Referenz auf „rapports officiels“). | H9: =IF(AND(E9<>"",D9<>""),IF(E9>=9,D9+30,IF(E9>=7,D9+14,IF(E9>=5,D9+7,IF(E9>=3,D9+3,D9+1)))),"") -> 45989 | I9: =IF(F9=0,"Neu",IF(AND(E9>=9,F9>=3),"Gemeistert",IF(E9>=9,"Gefestigt",IF(E9>=5,"In Arbeit","Ausbaufähig")))) -> Ausbaufähig
A10: 153 | B10: B2 – Partizip Perfekt: schwierige Angleichungen | C10: B2 | D10: 45986 | E10: 3 | F10: 1 | G10: Systematische Unsicherheit bei der Angleichung: fehlende Kongruenz bei être (réparées), keine Angleichung bei avoir + vorangestelltem COD (distribuées, écrites) sowie gelegentliche Über-Angleichung (lue statt lu); Regel noch nicht verinnerlicht. | H10: =IF(AND(E10<>"",D10<>""),IF(E10>=9,D10+30,IF(E10>=7,D10+14,IF(E10>=5,D10+7,IF(E10>=3,D10+3,D10+1)))),"") -> 45989 | I10: =IF(F10=0,"Neu",IF(AND(E10>=9,F10>=3),"Gemeistert",IF(E10>=9,"Gefestigt",IF(E10>=5,"In Arbeit","Ausbaufähig")))) -> Ausbaufähig
A11: 115 | B11: B1 – Uhrzeit & Dauer im Kontext | C11: B1 | D11: 45983 | E11: 6 | F11: 2 | G11: „depuis“ und „il y a“ werden überwiegend korrekt verwendet, aber es gibt noch Verwechslungen bei Dauerangaben mit „en“ vs. „pendant“ und der Stellung von Zeitangaben im Satz; einzelne Strukturfehler (z.B. „besoin en“) traten mehrfach auf. /// 1. wdh: Grundsätzliche Unterscheidung sitzt besser, aber noch Unsicherheiten bei „en“ (Dauer) vs. „dans“ (Frist/Zukunft), z.B. bei Deadline-Angaben („arriver dans eine heure“). Fehler bei Zeitangaben ohne Präposition (falsch: „dans le mercredi“ statt „mercredi prochain“). | H11: =IF(AND(E11<>"",D11<>""),IF(E11>=9,D11+30,IF(E11>=7,D11+14,IF(E11>=5,D11+7,IF(E11>=3,D11+3,D11+1)))),"") -> 45990 | I11: =IF(F11=0,"Neu",IF(AND(E11>=9,F11>=3),"Gemeistert",IF(E11>=9,"Gefestigt",IF(E11>=5,"In Arbeit","Ausbaufähig")))) -> In Arbeit
A12: 30 | B12: A1 – Zahlen 70–99 (soixante-dix, quatre-vingts, quatre-vingt-dix) | C12: A1 | D12: 45977 | E12: 8 | F12: 1 | G12: Formen und Struktur der Zahlen 70–99 sind weitgehend sicher, inklusive Bindestrichen und Plural-s bei „quatre-vingts“. Einzelne Flüchtigkeitsfehler treten auf (z.B. 99 statt 90 gewählt), aber das System ist verstanden. | H12: =IF(AND(E12<>"",D12<>""),IF(E12>=9,D12+30,IF(E12>=7,D12+14,IF(E12>=5,D12+7,IF(E12>=3,D12+3,D12+1)))),"") -> 45991 | I12: =IF(F12=0,"Neu",IF(AND(E12>=9,F12>=3),"Gemeistert",IF(E12>=9,"Gefestigt",IF(E12>=5,"In Arbeit","Ausbaufähig")))) -> In Arbeit
A13: 46 | B13: A2 – Objektpronomen COI (me/te/lui/nous/vous/leur) | C13: A2 | D13: 45977 | E13: 7 | F13: 1 | G13: „lui/leur“ wird in typischen Strukturen (parler à, donner à, expliquer à) überwiegend korrekt eingesetzt, auch mit anderen Pronomen kombiniert. Es gibt noch Interferenzen mit COD bei bestimmten Verben (z.B. Tendenz zu „leur“ bei Verben, die eigentlich ein direktes Objekt verlangen). | H13: =IF(AND(E13<>"",D13<>""),IF(E13>=9,D13+30,IF(E13>=7,D13+14,IF(E13>=5,D13+7,IF(E13>=3,D13+3,D13+1)))),"") -> 45991 | I13: =IF(F13=0,"Neu",IF(AND(E13>=9,F13>=3),"Gemeistert",IF(E13>=9,"Gefestigt",IF(E13>=5,"In Arbeit","Ausbaufähig")))) -> In Arbeit
... A46: 124 | B46: B1 – Erzähltechniken: Hintergrund vs. Vordergrund | C46: B1 | D46: 45983 | E46: 9 | F46: 1 | G46: Exzellente Anwendung. Sowohl in Lückentexten als auch im freien Text („faisait beau“ vs. „a dérobé“) wurde die Logik intuitiv richtig angewendet. Nur reflexive Verben (sich ausruhen) wurden dabei teils vergessen, die Zeitform war aber korrekt. | H46: =IF(AND(E46<>"",D46<>""),IF(E46>=9,D46+30,IF(E46>=7,D46+14,IF(E46>=5,D46+7,IF(E46>=3,D46+3,D46+1)))),"") -> 46013 | I46: =IF(F46=0,"Neu",IF(AND(E46>=9,F46>=3),"Gemeistert",IF(E46>=9,"Gefestigt",IF(E46>=5,"In Arbeit","Ausbaufähig")))) -> Gefestigt
A47: 1 | B47: A1 – Aussagesatz (S–V–O) | C47: A1 | F47: 0 | H47: =IF(AND(E47<>"",D47<>""),IF(E47>=9,D47+30,IF(E47>=7,D47+14,IF(E47>=5,D47+7,IF(E47>=3,D47+3,D47+1)))),"") | I47: =IF(F47=0,"Neu",IF(AND(E47>=9,F47>=3),"Gemeistert",IF(E47>=9,"Gefestigt",IF(E47>=5,"In Arbeit","Ausbaufähig")))) -> Neu | J47: ☐
A48: 2 | B48: A1 – Verneinung: ne … pas (umgangssprachlich oft ohne ne) | C48: A1 | F48: 0 | H48: =IF(AND(E48<>"",D48<>""),IF(E48>=9,D48+30,IF(E48>=7,D48+14,IF(E48>=5,D48+7,IF(E48>=3,D48+3,D48+1)))),"") | I48: =IF(F48=0,"Neu",IF(AND(E48>=9,F48>=3),"Gemeistert",IF(E48>=9,"Gefestigt",IF(E48>=5,"In Arbeit","Ausbaufähig")))) -> Neu | J48: ☐
A49: 3 | B49: A1 – Fragen: Intonation / est-ce que / einfache Inversion | C49: A1 | F49: 0 | H49: =IF(AND(E49<>"",D49<>""),IF(E49>=9,D49+30,IF(E49>=7,D49+14,IF(E49>=5,D49+7,IF(E49>=3,D49+3,D49+1)))),"") | I49: =IF(F49=0,"Neu",IF(AND(E49>=9,F49>=3),"Gemeistert",IF(E49>=9,"Gefestigt",IF(E49>=5,"In Arbeit","Ausbaufähig")))) -> Neu | J49: ☐
A50: 4 | B50: A1 – C'est / ce sont vs. il/elle est (Grundgebrauch) | C50: A1 | F50: 0 | H50: =IF(AND(E50<>"",D50<>""),IF(E50>=9,D50+30,IF(E50>=7,D50+14,IF(E50>=5,D50+7,IF(E50>=3,D50+3,D50+1)))),"") | I50: =IF(F50=0,"Neu",IF(AND(E50>=9,F50>=3),"Gemeistert",IF(E50>=9,"Gefestigt",IF(E50>=5,"In Arbeit","Ausbaufähig")))) -> Neu | J50: ☐
A51: 5 | B51: A1 – Il y a (es gibt) | C51: A1 | F51: 0 | H51: =IF(AND(E51<>"",D51<>""),IF(E51>=9,D51+30,IF(E51>=7,D51+14,IF(E51>=5,D51+7,IF(E51>=3,D51+3,D51+1)))),"") | I51: =IF(F51=0,"Neu",IF(AND(E51>=9,F51>=3),"Gemeistert",IF(E51>=9,"Gefestigt",IF(E51>=5,"In Arbeit","Ausbaufähig")))) -> Neu | J51: ☐
A52: 6 | B52: A1 – Satzverknüpfer: et, mais, parce que (Grundlagen) | C52: A1 | F52: 0 | H52: =IF(AND(E52<>"",D52<>""),IF(E52>=9,D52+30,IF(E52>=7,D52+14,IF(E52>=5,D52+7,IF(E52>=3,D52+3,D52+1)))),"") | I52: =IF(F52=0,"Neu",IF(AND(E52>=9,F52>=3),"Gemeistert",IF(E52>=9,"Gefestigt",IF(E52>=5,"In Arbeit","Ausbaufähig")))) -> Neu | J52: ☐
A53: 7 | B53: A1 – Artikel: bestimmt (le, la, les) | C53: A1 | F53: 0 | H53: =IF(AND(E53<>"",D53<>""),IF(E53>=9,D53+30,IF(E53>=7,D53+14,IF(E53>=5,D53+7,IF(E53>=3,D53+3,D53+1)))),"") | I53: =IF(F53=0,"Neu",IF(AND(E53>=9,F53>=3),"Gemeistert",IF(E53>=9,"Gefestigt",IF(E53>=5,"In Arbeit","Ausbaufähig")))) -> Neu | J53: ☐
A54: 8 | B54: A1 – Artikel: unbestimmt (un, une, des) | C54: A1 | F54: 0 | H54: =IF(AND(E54<>"",D54<>""),IF(E54>=9,D54+30,IF(E54>=7,D54+14,IF(E54>=5,D54+7,IF(E54>=3,D54+3,D54+1)))),"") | I54: =IF(F54=0,"Neu",IF(AND(E54>=9,F54>=3),"Gemeistert",IF(E54>=9,"Gefestigt",IF(E54>=5,"In Arbeit","Ausbaufähig")))) -> Neu | J54: ☐
A55: 9 | B55: A1 – Partitivartikel (du, de la, des) | C55: A1 | F55: 0 | H55: =IF(AND(E55<>"",D55<>""),IF(E55>=9,D55+30,IF(E55>=7,D55+14,IF(E55>=5,D55+7,IF(E55>=3,D55+3,D55+1)))),"") | I55: =IF(F55=0,"Neu",IF(AND(E55>=9,F55>=3),"Gemeistert",IF(E55>=9,"Gefestigt",IF(E55>=5,"In Arbeit","Ausbaufähig")))) -> Neu | J55: ☐
A56: 10 | B56: A1 – de nach Verneinung und Mengen (pas de, beaucoup de) | C56: A1 | F56: 0 | H56: =IF(AND(E56<>"",D56<>""),IF(E56>=9,D56+30,IF(E56>=7,D56+14,IF(E56>=5,D56+7,IF(E56>=3,D56+3,D56+1)))),"") | I56: =IF(F56=0,"Neu",IF(AND(E56>=9,F56>=3),"Gemeistert",IF(E56>=9,"Gefestigt",IF(E56>=5,"In Arbeit","Ausbaufähig")))) -> Neu | J56: ☐
A57: 11 | B57: A1 – Nomen: Genus & Pluralbildung | C57: A1 | F57: 0 | H57: =IF(AND(E57<>"",D57<>""),IF(E57>=9,D57+30,IF(E57>=7,D57+14,IF(E57>=5,D57+7,IF(E57>=3,D57+3,D57+1)))),"") | I57: =IF(F57=0,"Neu",IF(AND(E57>=9,F57>=3),"Gemeistert",IF(E57>=9,"Gefestigt",IF(E57>=5,"In Arbeit","Ausbaufähig")))) -> Neu | J57: ☐
A58: 12 | B58: A1 – Adjektive: Grundkongruenz & häufige Voranstellung (petit, grand, beau) | C58: A1 | F58: 0 | H58: =IF(AND(E58<>"",D58<>""),IF(E58>=9,D58+30,IF(E58>=7,D58+14,IF(E58>=5,D58+7,IF(E58>=3,D58+3,D58+1)))),"") | I58: =IF(F58=0,"Neu",IF(AND(E58>=9,F58>=3),"Gemeistert",IF(E58>=9,"Gefestigt",IF(E58>=5,"In Arbeit","Ausbaufähig")))) -> Neu | J58: ☐
... A248: 247 | B248: C2 – Tempusarchitektur in komplexen Textsorten (Erzählzeit, Perspektivwechsel, Analepsen/Prolepsen) | C248: C2 | F248: 0 | H248: =IF(AND(E248<>"",D248<>""),IF(E248>=9,D248+30,IF(E248>=7,D248+14,IF(E248>=5,D248+7,IF(E248>=3,D248+3,D248+1)))),"") | I248: =IF(F248=0,"Neu",IF(AND(E248>=9,F248>=3),"Gemeistert",IF(E248>=9,"Gefestigt",IF(E248>=5,"In Arbeit","Ausbaufähig")))) -> Neu | J248: ☐
A249: =A248+1 -> 248 | B249: C2 – Passé simple: aktive Beherrschung in Literatur/Essay (Bildung, unregelmäßige Stämme, Stilwert) | C249: C2 | F249: 0 | H249: =IF(AND(E249<>"",D249<>""),IF(E249>=9,D249+30,IF(E249>=7,D249+14,IF(E249>=5,D249+7,IF(E249>=3,D249+3,D249+1)))),"") | I249: =IF(F249=0,"Neu",IF(AND(E249>=9,F249>=3),"Gemeistert",IF(E249>=9,"Gefestigt",IF(E249>=5,"In Arbeit","Ausbaufähig")))) -> Neu | J249: ☐
A250: =A249+1 -> 249 | B250: C2 – Passé antérieur: Vorvergangenheit im literarischen Bericht (selten, aber produktiv) | C250: C2 | F250: 0 | H250: =IF(AND(E250<>"",D250<>""),IF(E250>=9,D250+30,IF(E250>=7,D250+14,IF(E250>=5,D250+7,IF(E250>=3,D250+3,D250+1)))),"") | I250: =IF(F250=0,"Neu",IF(AND(E250>=9,F250>=3),"Gemeistert",IF(E250>=9,"Gefestigt",IF(E250>=5,"In Arbeit","Ausbaufähig")))) -> Neu | J250: ☐
A251: =A250+1 -> 250 | B251: C2 – Imparfait narratif vs. descriptif: Effekte, Spannungsaufbau, Iterativ/Habituell | C251: C2 | F251: 0 | H251: =IF(AND(E251<>"",D251<>""),IF(E251>=9,D251+30,IF(E251>=7,D251+14,IF(E251>=5,D251+7,IF(E251>=3,D251+3,D251+1)))),"") | I251: =IF(F251=0,"Neu",IF(AND(E251>=9,F251>=3),"Gemeistert",IF(E251>=9,"Gefestigt",IF(E251>=5,"In Arbeit","Ausbaufähig")))) -> Neu | J251: ☐
A252: =A251+1 -> 251 | B252: C2 – Plus-que-parfait & Futur antérieur: inferenzielle Lesarten (Vermutung, Schluss) | C252: C2 | F252: 0 | H252: =IF(AND(E252<>"",D252<>""),IF(E252>=9,D252+30,IF(E252>=7,D252+14,IF(E252>=5,D252+7,IF(E252>=3,D252+3,D252+1)))),"") | I252: =IF(F252=0,"Neu",IF(AND(E252>=9,F252>=3),"Gemeistert",IF(E252>=9,"Gefestigt",IF(E252>=5,"In Arbeit","Ausbaufähig")))) -> Neu | J252: ☐
A253: =A252+1 -> 252 | B253: C2 – Futur dans le passé: konditionale Zukunft in Berichten, Presse, Stilabstufung | C253: C2 | F253: 0 | H253: =IF(AND(E253<>"",D253<>""),IF(E253>=9,D253+30,IF(E253>=7,D253+14,IF(E253>=5,D253+7,IF(E253>=3,D253+3,D253+1)))),"") | I253: =IF(F253=0,"Neu",IF(AND(E253>=9,F253>=3),"Gemeistert",IF(E253>=9,"Gefestigt",IF(E253>=5,"In Arbeit","Ausbaufähig")))) -> Neu | J253: ☐
A254: =A253+1 -> 253 | B254: C2 – Conditionnel journalistique (angeblich/Mutmaßung): Formen, Quellenabsicherung | C254: C2 | F254: 0 | H254: =IF(AND(E254<>"",D254<>""),IF(E254>=9,D254+30,IF(E254>=7,D254+14,IF(E254>=5,D254+7,IF(E254>=3,D254+3,D254+1)))),"") | I254: =IF(F254=0,"Neu",IF(AND(E254>=9,F254>=3),"Gemeistert",IF(E254>=9,"Gefestigt",IF(E254>=5,"In Arbeit","Ausbaufähig")))) -> Neu | J254: ☐
A255: =A254+1 -> 254 | B255: C2 – Conditionnel passé II (Nuancen, seltene Form) und stilistische Wirkung | C255: C2 | F255: 0 | H255: =IF(AND(E255<>"",D255<>""),IF(E255>=9,D255+30,IF(E255>=7,D255+14,IF(E255>=5,D255+7,IF(E255>=3,D255+3,D255+1)))),"") | I255: =IF(F255=0,"Neu",IF(AND(E255>=9,F255>=3),"Gemeistert",IF(E255>=9,"Gefestigt",IF(E255>=5,"In Arbeit","Ausbaufähig")))) -> Neu | J255: ☐
A256: =A255+1 -> 255 | B256: C2 – Hypotaxe mit gemischten Konditionalsätzen (kombinierte Typen, verschachtelte Perioden) | C256: C2 | F256: 0 | H256: =IF(AND(E256<>"",D256<>""),IF(E256>=9,D256+30,IF(E256>=7,D256+14,IF(E256>=5,D256+7,IF(E256>=3,D256+3,D256+1)))),"") | I256: =IF(F256=0,"Neu",IF(AND(E256>=9,F256>=3),"Gemeistert",IF(E256>=9,"Gefestigt",IF(E256>=5,"In Arbeit","Ausbaufähig")))) -> Neu | J256: ☐
A257: =A256+1 -> 256 | B257: C2 – wie wenn-Konstruktionen: comme si + imparfait/plus-que-parfait (Irrealität, Ironie) | C257: C2 | F257: 0 | H257: =IF(AND(E257<>"",D257<>""),IF(E257>=9,D257+30,IF(E257>=7,D257+14,IF(E257>=5,D257+7,IF(E257>=3,D257+3,D257+1)))),"") | I257: =IF(F257=0,"Neu",IF(AND(E257>=9,F257>=3),"Gemeistert",IF(E257>=9,"Gefestigt",IF(E257>=5,"In Arbeit","Ausbaufähig")))) -> Neu | J257: ☐
A258: =A257+1 -> 257 | B258: C2 – Subjonctif imparfait & plus-que-parfait: Erkennen und gezielter Einsatz in gehobener Schriftsprache | C258: C2 | F258: 0 | H258: =IF(AND(E258<>"",D258<>""),IF(E258>=9,D258+30,IF(E258>=7,D258+14,IF(E258>=5,D258+7,IF(E258>=3,D258+3,D258+1)))),"") | I258: =IF(F258=0,"Neu",IF(AND(E258>=9,F258>=3),"Gemeistert",IF(E258>=9,"Gefestigt",IF(E258>=5,"In Arbeit","Ausbaufähig")))) -> Neu | J258: ☐
A259: =A258+1 -> 258 | B259: C2 – Subjonctif nach Superlativen, Einzigkeit, emotionaler Bewertung (feine Grenzfälle) | C259: C2 | F259: 0 | H259: =IF(AND(E259<>"",D259<>""),IF(E259>=9,D259+30,IF(E259>=7,D259+14,IF(E259>=5,D259+7,IF(E259>=3,D259+3,D259+1)))),"") | I259: =IF(F259=0,"Neu",IF(AND(E259>=9,F259>=3),"Gemeistert",IF(E259>=9,"Gefestigt",IF(E259>=5,"In Arbeit","Ausbaufähig")))) -> Neu | J259: ☐
A260: =A259+1 -> 259 | B260: C2 – Subjonctif vs. Indicatif bei Meinungsverben unter Negation/Frage/Impersonalia (Nuancen) | C260: C2 | F260: 0 | H260: =IF(AND(E260<>"",D260<>""),IF(E260>=9,D260+30,IF(E260>=7,D260+14,IF(E260>=5,D260+7,IF(E260>=3,D260+3,D260+1)))),"") | I260: =IF(F260=0,"Neu",IF(AND(E260>=9,F260>=3),"Gemeistert",IF(E260>=9,"Gefestigt",IF(E260>=5,"In Arbeit","Ausbaufähig")))) -> Neu | J260: ☐
... A318: =A317+1 -> 317 | B318: C2 – Produktion: stilistisch angemessene Paraphrasen, Umformulierungen, Variation von Satzmustern | C318: C2 | F318: 0 | H318: =IF(AND(E318<>"",D318<>""),IF(E318>=9,D318+30,IF(E318>=7,D318+14,IF(E318>=5,D318+7,IF(E318>=3,D318+3,D318+1)))),"") | I318: =IF(F318=0,"Neu",IF(AND(E318>=9,F318>=3),"Gemeistert",IF(E318>=9,"Gefestigt",IF(E318>=5,"In Arbeit","Ausbaufähig")))) -> Neu | J318: ☐

Sheet Sheet3

Sheet Session Feedback
A1: Session | B1: Feedback
A2: Session 1 | B2: Stark: Du integrierst viele Zielstrukturen (Datum, depuis, si + imparfait → conditionnel, Futur/Futur antérieur) und nutzt mehrere Quantoren – super! Noch unsicher: Feinheiten bei Quantoren (la plupart de/des), idiomatisches Französisch (ne… que, se joindre à), sowie Wortstellung/Orthografie (Akzente, Bindestriche). 3 konkrete Tipps Quantoren-Formel merken: beaucoup/peu/assez/trop + de + Nomen la plupart des + allgemeines Nomen / de + Possessiv aucun(e) … ne + Verb Zukunft nach „quand/lorsque“: Gleichzeitigkeit: Quand tu arriveras, on mangera. Vorzeitigkeit: Quand tu auras fini, on ira. „nur“ = ne… que: Sag dir innerlich „nur = ne… que“, z. B. Je n’ai que deux heures.
A3: Session 2 | B3: Phase 4 – Reflexion Was lief gut 👍 y / en: Position vor dem Verb und in der Negation sitzt (z. B. n’y pensons plus, j’en ai quelques-unes). Futur antérieur: Form gebildet und sinnvoll eingesetzt (j’aurai pris, je serai sorti). Subjonctif: Auslöser erkannt (il faut que… → que vous soyez). dont / ce dont: Grundidee klar; du nutzt dont oft korrekt (dont je parle). Wo noch Unsicherheit ist 🔧 ce dont vs. ce que / ce qui: Du nimmst manchmal dont, obwohl kein de-Bezug da ist (eigentlich ce que/ce qui). Wortwahl & Idiomatik: oublier de (nicht perdre), partir für „losgehen“. Kleinigkeiten: demie nach heure; Artikel (une douche), Präpo bei Räumen (dans la salle de bains), Angleichungen (arrivés im Plural). 3 konkrete Tipps 🎯 „de-Test“ für dont – Ersetze dein Relativpronomen testweise mit de + NOM. – Klingt’s natürlich? → dont. Wenn nicht → que/qui. Ex.: C’est exactement ___ je t’ai parlé. → parler de ⇒ dont. Mini-Check für y und en y ↔ „dorthin/darin“ (ersetzt à + lieu/chose). en ↔ „davon/welche“ (ersetzt de + chose/Quantität). Stell dir den deutschen Ersatz vor: Wenn du dorthin/darin sagen würdest → y; wenn davon/wie viele → en. Futur antérieur in Ketten Bau Standardmuster: Quand / Dès que + futur antérieur, Hauptsatz futur simple. Merksatz: „Wenn X fertig sein wird, werde ich Y tun.“ 1-Min-Drill: Schreibe täglich 2 Sätze mit quand/dès que/une fois que.
A4: Session 3 | B4: 3. Phase 4 – Reflexion Was lief gut? Si-Sätze Typ 1 & 2: Du setzt die Strukturen schon ziemlich sicher: s’il fait beau, nous pourrons… ✅ Si j’étais en forme, je jouerais… ✅ Farben & Unveränderlichkeit: une chemise orange ✅ (unveränderlich) des chaussures bleues ✅ (angepasst) Zeitangaben: Il y a trois ans, j’y suis allé… ✅ Uhrzeit mit six heures et demie ✅ Du baust schon recht natürliche Sätze, die inhaltlich sehr gut verständlich sind. Wo sind noch Unsicherheiten? en vs. pendant vs. dans (Zeit): en deux heures (Dauer / wie lange man braucht) vs. pendant deux heures (zwei Stunden lang) dans deux heures (in zwei Stunden, zukünftiger Startpunkt) en vs. dans (Ort): dans notre ville vs. en ville dans le week-end ist falsch → einfach le week-end Kleine Dinge wie: Adjektivstellung (un joli restaurant), „samedi prochain“, „ce jour-là“. 4. Konkrete Tipps für dich 🧠✨ Tipp 1 – Si-Sätze im Kopf „programmieren“ Mach dir zwei Mini-Formeln klar: Typ 1 (real): Si + présent → futur simple → Si j’ai le temps, je viendrai. Typ 2 (irreal/hypothetisch): Si + imparfait → conditionnel → Si j’avais le temps, je viendrais. Wenn du einen Satz mit „wenn“ bildest, check kurz: ➡ Ist das real oder eher hypothetisch? → dann greifst du zur passenden Formel. Tipp 2 – en / dans / pendant in der Zeit en + Zeitdauer: „ich brauche so lange dafür“ → Je peux finir ce livre en trois jours. dans + Zeitdauer: „es beginnt in …“ → Je vais partir dans deux jours. pendant + Zeitdauer: „so lange hat es gedauert / dauert es“ → J’ai travaillé pendant deux heures. Wenn du „vor X Jahren“ sagen willst: → il y a X ans Tipp 3 – Farben: Nur manche bleiben stur Merksatz: Einfache Farben: passen sich an → des chaussures bleues, des fleurs rouges Zusammengesetzte Farben oder von Nomen abgeleitet: unveränderlich → une chemise orange, des pulls bleu clair, des pantalons marron Du hast das mit orange schon sehr gut benutzt, das kannst du bewusst weiterspielen.
A5: Session 4 | B5: Nice, Reflexionsmodus aktiviert 🧪🧠 ## 1. Gesamtbild Du bist **klar im B2-Land unterwegs**: Du traust dich, komplexe Strukturen zu benutzen (si-Sätze, doppelte Pronomen, y/en, Zahlen + Kontext) und machst vor allem **Fortgeschrittenenfehler**, nicht Anfängerfehler. Das ist ein gutes Zeichen: dein System ist da, nur die Feinjustierung fehlt noch. --- ## 2. Was gut lief – nach Themen ### 🔹 Demonstrativpronomen (celui/celle/ceux/celles) **Stark:** * Du setzt sie bewusst ein, nicht zufällig. * Du triffst Genus und Zahl oft schon richtig (*celle/celles* für Rezepte / Sachen im Femininum etc.). **Noch wackelig:** * Manchmal verwendest du **celui** dort, wo einfach **ce / c’ / il** natürlicher wäre (*celui était très bien* → *c’était très bien*). * Einmal hast du *ceux* als Art Objektpronomen benutzt (*pour payer ceux*) → da ist eigentlich **les** (COD-Pronomen) gefragt. 👉 Grundmuster sitzt, Feintuning ist: **„Ersetze ich ein Nomen (celui/celle) oder beschreibe ich es nur (ce/cet/cette/ces)?“** --- ### 🔹 Zahlen 70–99 **Stark:** * Formen wie *soixante-douze, quatre-vingt-huit, quatre-vingt-quatorze, quatre-vingt-dix-neuf* hast du sicher getroffen. * Auch das Prinzip *soixante-dix / quatre-vingts / quatre-vingt-dix* ist klar. **Mini-Baustelle:** * Du hast einmal 90 als 99 formuliert → das ist eher ein Konzentrations- als ein Wissensfehler. --- ### 🔹 COD / COI & Pronomenreihenfolge **Stark:** * Du setzt **le/la/les** vs. **lui/leur** meist richtig ein, besonders nach der kurzen Korrektur von *je leur écoute* → *je les écoute*. * Du hast korrekte Sequenzen wie **je le lui donne**, **nous le leur expliquons**, **je le lui ai payé**, **je leur en donne**, **il lui en parle**, **il les lui envoie** gebaut. Das ist ganz klar B2-Niveau. **Noch wackelig:** * Gelegentlich verrutscht das **richtige Pronomen** (Genus/Zahl), z.B. *Je les lui prête* statt *Je le leur prête* (le livre). * Bei Inversion (*prêtes-tu…*) sind die Pronomen einmal an die falsche Stelle gerutscht (*prêtes-tu la lui ?* statt *La lui prêtes-tu ?*). --- ### 🔹 Si-Sätze Typ 3 & gemischte Perioden **Stark:** * Strukturen wie *Si j’avais su…, j’aurais préparé…* *Si nous avions eu…, nous aurions visité…* *Si j’avais eu assez d’argent, …* kamen bei dir **direkt in der korrekten Form**. Das ist keine Kleinigkeit. * Auch gemischte Perioden (Vergangenheit → Gegenwart) hast du im Prinzip richtig aufgebaut (*Si j’avais mieux dormi hier, je serais moins fatigué aujourd’hui.* – mit kleinen Stellungsfehlern). **Noch wackelig:** * Hilfsverben geraten dir manchmal durcheinander: *si tu étais été* statt **si tu avais été**. * Einmal hast du Futur statt Conditionnel genutzt (*nous aurons déjà terminé* statt **nous aurions déjà terminé**). * In einem Satz war das Subjekt verdreht: du sagtest, *du* wärst zerstreut, aber *ich* hätte den Termin vergessen. --- ### 🔹 Pronomenkette (volle Klitik-Sequenz) **Stark:** * Du kennst die Reihenfolge praktisch: **(me/te/se/nous/vous) → le/la/les → lui/leur → y → en** Und du verwendest sie korrekt in vielen Sätzen. * Du benutzt **y** und **en** sinnvoll und kombinierst sie mit anderen Pronomen (*Je lui en parle, Je leur en donne, Nous y allons souvent*). **Noch wackelig:** * Bei sehr dichter Kombi mit Zahl + y/en wurdest du etwas unnatürlich (*Nous y allons souvent et en passons toujours 3 jours* – verständlich, aber stilistisch holprig). * Inversion + Pronomen (Fragesätze) ist noch nicht automatisiert. --- ## 3. Konkrete Tipps (2–3 Fokus-Hebel) Lass uns das auf wirklich **3 Hebel** runterkochen, die dir maximal viel bringen: ### ✅ Tipp 1: Mini-Routine für „celui / celle“ Wenn du **celui/celle/ceux/celles** verwenden willst, geh innerlich immer diese Checkliste durch: 1. **Welches Nomen ersetze ich?** → Genus/Zahl klarmachen: *le pull* → celui, *la robe* → celle, *les chaussures* → celles usw. 2. **Steht das Nomen noch im Satz?** * Wenn ja → **kein** celui, dann brauchst du *ce/cet/cette/ces*. * Wenn nein → **celui/celle/etc.** ist okay. 3. **Kann ich es klarer machen mit** * *celui-ci / celui-là* (dieser hier / jener dort) * oder *celui que…* (der, den …)? Wenn du das 20–30× bewusst machst, rutscht es ins Muskelgedächtnis. --- ### ✅ Tipp 2: „Reflex-Sätze“ für Si-Sätze Lern dir 2–3 feste **Reflex-Sätze** auswendig, die du als Schablone benutzt: * **Typ 3 (irreale Vergangenheit):** > *Si j’avais su, je ne serais pas venu.* > *Si j’avais eu plus de temps, j’aurais fini le projet.* * **Gemischt (Vergangenheit → Gegenwart):** > *Si j’avais mieux dormi, je serais plus concentré aujourd’hui.* * **Gegenwartsbedingung → vergangene Folge:** > *Si je n’étais pas si distrait, je n’aurais pas oublié le rendez-vous.* Beim Produzieren neuer Sätze kannst du dich immer fragen: „Passt das in eines dieser Muster? Wenn ja → Zeitformen daran ausrichten.“ --- ### ✅ Tipp 3: Ein paar Kernverben als COD/COI-Anker Baue dir eine kleine mentale Liste mit Verben, bei denen du **automatisch** an COD oder COI denkst: * **Immer COD (le/la/les)**: *écouter, aider, attendre, voir, aimer, comprendre* → *Je **les** écoute*, *Je **l’**attends*, *Je **les** aide*, etc. * **Oft COI (lui/leur)**: *parler à, téléphoner à, écrire à, expliquer à (personne)* → *Je **lui** parle*, *Je **leur** écris*, *Je **le** **leur** explique*. Wenn du neue Verben lernst, kannst du sie direkt in diese Schubladen einsortieren. Das macht die Pronomenwahl irgendwann fast automatisch. --- Unterm Strich: du bist an einem Punkt, wo **gezielte Wiederholung + viel freie Anwendung** ideal sind. Beim nächsten Mal könnte man z.B. einen Mini-Rollenspiel-Tag machen („stressiger Arbeitstag mit verpassten Terminen“), in dem du spontan sprichst und ich live die Grammatik einflechte.
A6: Session 5 | B6: 🌟 Phase 4 – Kurze Reflexion Was schon richtig gut läuft Du setzt die Strukturen aktiv ein, nicht nur in Mini-Sätzen → super wichtig für B1/B2. Passé composé / imparfait: Grundidee sitzt, du verwendest beides sinnvoll. Negation: ni… ni… und aucun sind da, nur kleine Artikeldetails. Subjonctif: richtige Auslöser gewählt (souhaiter que, ne pas croire que). Woran du noch feilen kannst Kleine Wörter & Präpositionen: chez moi / à la maison / dans la cuisine, non plus statt aussi in negativen Sätzen. Zeitangaben mit passé récent: lieber einfach: Mes amis viennent de partir oder Il y a 20 minutes, ils sont partis… – nicht alles auf einmal mischen. Akzente & Kleinkram: thé, café, à, tôt – fürs Schreiben wichtig, fürs Sprechen egal, aber auf B1/B2 lohnt sich die Mühe. 3 konkrete Tipps für dich 🧱 Merkblöcke bauen: Schreib dir auf eine Karte: Je n’ai aucun… + Singular Je n’ai aucun pain / aucun problème / aucune idée und lies sie 1–2 Tage immer mal wieder. 🎭 Mini-Sätze mit Subjonctif automatisieren: Täglich 5 Sätze mit: Je veux que… Je suis content que… Je ne crois pas que… → So wird dein Gehirn an den Subjonctif-Auslöser gewöhnt. ⏳ Passé récent vs. passé composé üben: Mach dir Paare: Je viens de manger. ↔ J’ai mangé. Ils viennent d’arriver. ↔ Ils sont arrivés. und versuch, jeweils auf Deutsch zu unterscheiden: „gerade eben“ vs. „irgendwann (neulich/heute/gestern)“. Wenn du magst, können wir als Nächstes eine kurze Dialogübung machen, in der du spontan mit venir de, être en train de, ni… ni… und Subjonctif antwortest – eher wie im echten Gespräch 🇫🇷🗣️
A7: Session 6 | B7: 🔚 Phase 4 – Kurze Reflexion ✅ Was schon richtig gut lief Du nutzt Plus-que-parfait und Si-Sätze Typ 3 aktiv – auch wenn Formen manchmal noch holpern, ist die Struktur da. Du verwendest Adverbien (beaucoup, peut-être, plus) sinnvoll. Du hast ein Beispiel mit tonischem Pronomen nach Präposition: Avec elle… ✅ Inhaltlich schreibst du sehr persönlich und klar – super für den Lernfortschritt. 🎯 3 konkrete Tipps für diese Konzepte Plus-que-parfait bauen wie Formel: → Imparfait von avoir/être + participe passé mourir → elle était morte partir → nous étions partis finir → j’avais fini Si-Sätze Typ 3 – nie „aurais“ im si-Teil: immer: si + plus-que-parfait und in der Folge: conditionnel passé → Si j’avais su, je t’aurais aidé. Adverb-Stellung im Satz merken: meistens: Subjekt + Verb + Adverb → Je travaille beaucoup. / Nous parlons souvent avec eux. déjà / toujours / souvent stehen oft zwischen Hilfsverb und Partizip: → Nous avions déjà commencé. / Ils ont toujours été gentils. Wenn du möchtest, können wir als nächste Mini-Übung deinen Text leicht umschreiben, damit du ce qui / ce que / ce dont auch noch bewusst einbaust (z.B. Ce qui m’a le plus touché, c’est…).
A8: Session 7 | B8: 🎉 Bilan de la session Tu as fait d'énormes progrès aujourd'hui ! ✅ Causatif (Faire + Infinitif) : C'est acquis. La phrase "J'ai fait bloquer ma carte par la réceptionniste" était parfaite grammaticalement. ✅ Discours Indirect : Excellent usage de "de ne pas m'énerver". ✅ Temps du passé : La distinction Imparfait (faisait/reposais) et Passé Composé (a dérobé) est claire. ⚠️ À surveiller : Les petits mots de liaison (connecteurs) et les prépositions de temps (en/dans) demandent encore un peu de vigilance.

Sheet Anleitung
A1: 📖 Anleitung - Französisch Grammatik Tracker
A4: 🎯 Grundlegende Nutzung
A6: 1. Grammatik Tracker Tab | B6: Hier findest du alle 246 französischen Grammatikkonzepte von A1 bis C1
A8: 2. Nach einer Lernsession | B8: Trage folgende Daten ein:
A9: - Letzte Wiederholung | B9: Datum im Format TT.MM.JJJJ (z.B. 11.11.2025)
A10: - Score (0-10) | B10: Deine Selbsteinschätzung: 0-2=Anfänger, 3-4=Ausbaufähig, 5-6=Mittelmäßig, 7-8=Gut, 9-10=Exzellent
A11: - Notizen | B11: Optionale Anmerkungen zu deinem Lernprozess
A13: 3. Automatische Berechnungen
A14: - Anzahl Wiederholungen | B14: Wird automatisch erhöht wenn du einen Score einträgst
A15: - Nächste Wiederholung | B15: Wird basierend auf deinem Score berechnet:
A16: • Score 9-10 | B16: → in 30 Tagen
A17: • Score 7-8 | B17: → in 14 Tagen
A18: • Score 5-6 | B18: → in 7 Tagen
A19: • Score 3-4 | B19: → in 3 Tagen
A20: • Score 0-2 | B20: → in 1 Tag
A21: - Status | B21: Wird automatisch berechnet:
A22: • Neu | B22: Noch nicht geübt
A23: • Ausbaufähig | B23: Score unter 5
A24: • In Arbeit | B24: Score 5-8
A25: • Gefestigt | B25: Score 9-10
A26: • Gemeistert | B26: Score 9-10 + mindestens 3 Wiederholungen
A28: 🔍 Filtern & Sortieren
A30: • Filter aktivieren | B30: Klicke auf die Dropdown-Pfeile in der Header-Zeile
A31: • Nach Niveau filtern | B31: Wähle A1, A2, B1, B2 oder C1
A32: • Nach Status filtern | B32: Wähle Neu, Ausbaufähig, In Arbeit, Gefestigt oder Gemeistert
A33: • Sortieren | B33: Klicke auf Spaltenüberschriften zum Sortieren
A35: ✅ Konzepte auswählen
A37: • Auswahl-Spalte | B37: Markiere Konzepte mit einem "x" in Spalte J
A38: • Für AI-Session | B38: Filtere nach ausgewählten Konzepten und kopiere die Liste
A40: 📊 Dashboard
A42: • Statistik-Übersicht | B42: Zeigt deinen Gesamtfortschritt
A43: • Niveau-Verteilung | B43: Anzahl Konzepte pro Niveau
A44: • Fortschrittsanzeige | B44: Wie viele Konzepte du bereits bearbeitet hast
A46: 💡 Tipps
A48: • Regelmäßig üben | B48: Arbeite täglich an 3-5 Konzepten
A49: • Priorisierung | B49: Fokussiere auf fällige Wiederholungen (Nächste Wiederholung in der Vergangenheit)
A50: • Notizen nutzen | B50: Halte Schwierigkeiten oder Beispiele fest
A51: • Ehrlich bewerten | B51: Score nur vergeben wenn du das Konzept wirklich verstehst
A53: 📥 Datensicherung
A55: • Regelmäßig speichern | B55: Drücke Strg+S (Windows) oder Cmd+S (Mac)
...

Sheet Prompts
A1: Initialer Lernsession-Prompt | B1: # Französisch Grammatik Lernsession ## Zu übende Konzepte: [HIER DIE 2-5 AUSGEWÄHLTEN KONZEPTE EINFÜGEN] ## Deine Rolle als Lehrer: Du bist ein erfahrener Französischlehrer, der eine intensive, aber abwechslungsreiche Lernsession gestaltet. Dein Ziel ist es, dass ich die oben genannten Grammatikkonzepte durch aktive Anwendung verinnerlichte. ## Struktur der Lernsession: ### Phase 1: Kurze Wiederholung (5 Min) - Erkläre jedes Konzept prägnant mit 1-2 Beispielsätzen - Hebe die häufigsten Fehlerquellen hervor - Frage mich, ob ich Verständnisfragen habe ### Phase 2: Gezielte Übungen (25-30 Min) Führe mich durch verschiedene Übungstypen. Wechsle die Formate ab: 1. **Lückentexte**: Sätze mit Lücken, die ich ergänzen muss 2. **Übersetzungsübungen**: Deutsch → Französisch (realistische Alltagssätze) 3. **Fehlerkorrektur**: Zeige mir fehlerhafte Sätze, die ich korrigieren muss 4. **Satzbildung**: Gib mir Vorgaben (Subjekt, Verb, Objekt), aus denen ich Sätze bilde 5. **Kontextaufgaben**: Kurze Dialoge oder Situationen, in denen ich die Konzepte anwenden muss 6. **Spontane Anwendung**: Stelle mir Fragen, die ich spontan mit den Konzepten beantworten muss **Wichtig**: - Präsentiere maximal 3-5 Aufgaben gleichzeitig - Warte auf meine Antworten, bevor du weitermachst - Gib sofort Feedback: ✓ richtig oder korrigiere mit Erklärung - Steigere den Schwierigkeitsgrad graduell - Kombiniere mehrere Konzepte in fortgeschrittenen Übungen ### Phase 3: Komplexe Anwendung (10 Min) - Stelle mir eine realistische Aufgabe (z.B. "Beschreibe deinen gestrigen Tag" oder "Erkläre, was du nächstes Wochenende machen wirst") - Die Aufgabe muss alle geübten Konzepte integrieren - Korrigiere meinen Text und erkläre Fehler ### Phase 4: Reflexion - Fasse zusammen, was gut lief und wo noch Unsicherheiten bestehen - Gib mir 2-3 konkrete Tipps, worauf ich bei diesen Konzepten besonders achten sollte ## Dein Verhalten: - Sei ermutigend, aber ehrlich bei Fehlern - Erkläre Fehler immer mit der zugrundeliegenden Regel - Verwende keine Fachbegriffe ohne Erklärung - Frage nach, wenn ich zögere: "Bist du dir sicher?" - Passe den Schwierigkeitsgrad an meine Leistung an Starte jetzt mit Phase 1!
A2: abschluss | B2: # Lernsession Abschluss & Dokumentation Die Lernsession ist beendet. Erstelle jetzt eine strukturierte Auswertung für meine Excel-Datei. ## Für jedes geübte Grammatikkonzept, erstelle folgendes Format: **[Grammatikkonzept-Name]** - **Datum**: [Heutiges Datum im Format TT.MM.YYYY] - **Score**: [0-10 nach den Kriterien unten] - **Notizen**: [Präzise Beschreibung der Schwierigkeiten in 1-2 Sätzen] - **Wiederholungsintervall**: [Empfehlung in Tagen: 1, 3, 7, 14, 30] --- ### Score-Kriterien (0-10): **9-10 (Exzellent)**: - Alle Aufgaben richtig gelöst (>95%) - Spontane, fehlerfreie Anwendung - Auch bei komplexen Kombinationen sicher - Keine Erklärungen mehr nötig **7-8 (Gut gefestigt)**: - Meiste Aufgaben richtig (80-95%) - Kleine Flüchtigkeitsfehler möglich - Bei Nachfrage kann ich Regel erklären - In einfachen Kontexten sicher **5-6 (Mittelmäßig)**: - Etwa die Hälfte richtig (50-80%) - Konzept verstanden, aber noch unsichere Anwendung - Brauche noch Bedenkzeit - Mehrere gleichartige Fehler **3-4 (Ausbaufähig)**: - Weniger als die Hälfte richtig (<50%) - Grundverständnis vorhanden, aber viele Fehler - Verwechslungen mit ähnlichen Konzepten - Brauche oft Hilfestellungen **1-2 (Anfänger)**: - Kaum richtige Anwendungen (<25%) - Regel noch nicht verstanden - Systematische Fehler - Konzept ist neu oder wurde vergessen **0 (Nicht geübt)**: - Konzept wurde in dieser Session nicht behandelt --- **Notizen-Richtlinien**: Beschreibe konkret: - Welche Teilaspekte des Konzepts waren problematisch? (z.B. "Verwechslung zwischen COD und COI") - Welche spezifischen Fehler traten wiederholt auf? (z.B. "Vergesse Angleichung bei Passé composé mit être") - Gibt es Interferenzen mit anderen Konzepten? (z.B. "Verwechselt qui/que in Relativsätzen") Gib die Auswertung jetzt in diesem Format aus, sodass ich die Daten direkt in meine Excel-Datei übertragen kann.
